Workbook
Name Slicer_: #N/A
Name Slicer_Country: #N/A
Name Slicer_Months: #N/A
Name Slicer_Product: #N/A
Name Slicer_Sales_Person: #N/A

Sheet Home

Sheet Raw_data
A1: Date | B1: Product | C1: Sales Person | D1: Boxes Shipped | E1: Amount ($) | F1: Country
A2: 44598 | B2: Pain Relief Tablets | C2: Divya Mehra | D2: 7 | E2: 67.43 | F2: Australia
A3: 44597 | B3: Antiseptic Cream | C3: Nikhil Batra | D3: 18 | E3: 421.46 | F3: Canada
A4: 44611 | B4: Cough Syrup | C4: Ritika Shah | D4: 2 | E4: 48.25 | F4: UK
A5: 44648 | B5: Pain Relief Tablets | C5: Nikhil Batra | D5: 5 | E5: 59.89 | F5: UK
A6: 44578 | B6: Digestive Enzyme | C6: Ritika Shah | D6: 8 | E6: 147.73 | F6: USA
A7: 44601 | B7: Digestive Enzyme | C7: Ritika Shah | D7: 18 | E7: 400.87 | F7: USA
A8: 44742 | B8: Antiseptic Cream | C8: Nikhil Batra | D8: 3 | E8: 50.35 | F8: Australia
A9: 44767 | B9: Eye Drops | C9: Ritika Shah | D9: 13 | E9: 282.43 | F9: USA
A10: 44640 | B10: Nasal Spray | C10: Priya Singh | D10: 17 | E10: 394.01 | F10: UK
A11: 44585 | B11: Antiseptic Cream | C11: Sneha Iyer | D11: 7 | E11: 89.29 | F11: Australia
A12: 44678 | B12: Cough Syrup | C12: Divya Mehra | D12: 11 | E12: 150.73 | F12: Canada
A13: 44610 | B13: Pain Relief Tablets | C13: Ritika Shah | D13: 5 | E13: 63.41 | F13: USA
... A334: 44784 | B334: Digestive Enzyme | C334: Rajesh Patel | D334: 3 | E334: 65.98 | F334: UK

Sheet Cleanning_data
A1: Date | B1: Product | C1: Sales Person | D1: Boxes Shipped | E1: Amount ($) | F1: Country | G1: Duplicates | I1: Columns | J1: NULL | K1: AVE | L1: MEDIAN | M1: MODE
A2: =IF(Raw_data!A2="",NA(),Raw_data!A2) -> 44598 | B2: =IF(Raw_data!B2="",NA(),Raw_data!B2) -> Pain Relief Tablets | C2: =IF(Raw_data!C2="",NA(),Raw_data!C2) -> Divya Mehra | D2: =IF(Raw_data!D2="",NA(),Raw_data!D2) -> 7 | E2: =IF(Raw_data!E2="",NA(),Raw_data!E2) -> 67.43 | F2: =IF(Raw_data!F2="",NA(),Raw_data!F2) -> Australia | G2: =COUNTIFS(A:A,A2,B:B,B2,C:C,C2,D:D,D2,E:E,E2,F:F,F2) -> 1 | I2: Date | J2: {=SUM(IF(ISERROR(A2:A334),1,0))} -> 0
A3: =IF(Raw_data!A3="",NA(),Raw_data!A3) -> 44597 | B3: =IF(Raw_data!B3="",NA(),Raw_data!B3) -> Antiseptic Cream | C3: =IF(Raw_data!C3="",NA(),Raw_data!C3) -> Nikhil Batra | D3: =IF(Raw_data!D3="",NA(),Raw_data!D3) -> 18 | E3: =IF(Raw_data!E3="",NA(),Raw_data!E3) -> 421.46 | F3: =IF(Raw_data!F3="",NA(),Raw_data!F3) -> Canada | G3: =COUNTIFS(A:A,A3,B:B,B3,C:C,C3,D:D,D3,E:E,E3,F:F,F3) -> 1 | I3: Product | J3: {=SUM(IF(ISERROR(B2:$B$334),1,0))} -> 0 | M3: Antiseptic Cream
A4: =IF(Raw_data!A4="",NA(),Raw_data!A4) -> 44611 | B4: =IF(Raw_data!B4="",NA(),Raw_data!B4) -> Cough Syrup | C4: =IF(Raw_data!C4="",NA(),Raw_data!C4) -> Ritika Shah | D4: =IF(Raw_data!D4="",NA(),Raw_data!D4) -> 2 | E4: =IF(Raw_data!E4="",NA(),Raw_data!E4) -> 48.25 | F4: =IF(Raw_data!F4="",NA(),Raw_data!F4) -> UK | G4: =COUNTIFS(A:A,A4,B:B,B4,C:C,C4,D:D,D4,E:E,E4,F:F,F4) -> 1 | I4: Sales Person | J4: {=SUM(IF(ISERROR(C2:$C$334),1,0))} -> 0 | M4: Rajesh Patel
A5: =IF(Raw_data!A5="",NA(),Raw_data!A5) -> 44648 | B5: =IF(Raw_data!B5="",NA(),Raw_data!B5) -> Pain Relief Tablets | C5: =IF(Raw_data!C5="",NA(),Raw_data!C5) -> Nikhil Batra | D5: =IF(Raw_data!D5="",NA(),Raw_data!D5) -> 5 | E5: =IF(Raw_data!E5="",NA(),Raw_data!E5) -> 59.89 | F5: =IF(Raw_data!F5="",NA(),Raw_data!F5) -> UK | G5: =COUNTIFS(A:A,A5,B:B,B5,C:C,C5,D:D,D5,E:E,E5,F:F,F5) -> 1 | I5: Boxes Shipped | J5: {=SUM(IF(ISERROR(D1:$D$334),1,0))} -> 0 | K5: =ROUND(_xlfn.AGGREGATE(1,6,D2:$D$334),2) -> 10.47 | L5: =ROUND(_xlfn.AGGREGATE(12,6,D2:$D$334),2) -> 11
A6: =IF(Raw_data!A6="",NA(),Raw_data!A6) -> 44578 | B6: =IF(Raw_data!B6="",NA(),Raw_data!B6) -> Digestive Enzyme | C6: =IF(Raw_data!C6="",NA(),Raw_data!C6) -> Ritika Shah | D6: =IF(Raw_data!D6="",NA(),Raw_data!D6) -> 8 | E6: =IF(Raw_data!E6="",NA(),Raw_data!E6) -> 147.73 | F6: =IF(Raw_data!F6="",NA(),Raw_data!F6) -> USA | G6: =COUNTIFS(A:A,A6,B:B,B6,C:C,C6,D:D,D6,E:E,E6,F:F,F6) -> 1 | I6: Amount | J6: {=SUM(IF(ISERROR(E2:E334),1,0))} -> 0 | K6: =ROUND(_xlfn.AGGREGATE(1,6,E2:$E$334),2) -> 176.96 | L6: =ROUND(_xlfn.AGGREGATE(12,6,E2:$E$334),2) -> 156.92
A7: =IF(Raw_data!A7="",NA(),Raw_data!A7) -> 44601 | B7: =IF(Raw_data!B7="",NA(),Raw_data!B7) -> Digestive Enzyme | C7: =IF(Raw_data!C7="",NA(),Raw_data!C7) -> Ritika Shah | D7: =IF(Raw_data!D7="",NA(),Raw_data!D7) -> 18 | E7: =IF(Raw_data!E7="",NA(),Raw_data!E7) -> 400.87 | F7: =IF(Raw_data!F7="",NA(),Raw_data!F7) -> USA | G7: =COUNTIFS(A:A,A7,B:B,B7,C:C,C7,D:D,D7,E:E,E7,F:F,F7) -> 1 | I7: Country | J7: {=SUM(IF(ISERROR(F2:F334),1,0))} -> 0 | M7: USA
A8: =IF(Raw_data!A8="",NA(),Raw_data!A8) -> 44742 | B8: =IF(Raw_data!B8="",NA(),Raw_data!B8) -> Antiseptic Cream | C8: =IF(Raw_data!C8="",NA(),Raw_data!C8) -> Nikhil Batra | D8: =IF(Raw_data!D8="",NA(),Raw_data!D8) -> 3 | E8: =IF(Raw_data!E8="",NA(),Raw_data!E8) -> 50.35 | F8: =IF(Raw_data!F8="",NA(),Raw_data!F8) -> Australia | G8: =COUNTIFS(A:A,A8,B:B,B8,C:C,C8,D:D,D8,E:E,E8,F:F,F8) -> 1
A9: =IF(Raw_data!A9="",NA(),Raw_data!A9) -> 44767 | B9: =IF(Raw_data!B9="",NA(),Raw_data!B9) -> Eye Drops | C9: =IF(Raw_data!C9="",NA(),Raw_data!C9) -> Ritika Shah | D9: =IF(Raw_data!D9="",NA(),Raw_data!D9) -> 13 | E9: =IF(Raw_data!E9="",NA(),Raw_data!E9) -> 282.43 | F9: =IF(Raw_data!F9="",NA(),Raw_data!F9) -> USA | G9: =COUNTIFS(A:A,A9,B:B,B9,C:C,C9,D:D,D9,E:E,E9,F:F,F9) -> 1 | I9: Product | J9: Values count | L9: Country | M9: Values count | O9: Sales Person | P9: values count
A10: =IF(Raw_data!A10="",NA(),Raw_data!A10) -> 44640 | B10: =IF(Raw_data!B10="",NA(),Raw_data!B10) -> Nasal Spray | C10: =IF(Raw_data!C10="",NA(),Raw_data!C10) -> Priya Singh | D10: =IF(Raw_data!D10="",NA(),Raw_data!D10) -> 17 | E10: =IF(Raw_data!E10="",NA(),Raw_data!E10) -> 394.01 | F10: =IF(Raw_data!F10="",NA(),Raw_data!F10) -> UK | G10: =COUNTIFS(A:A,A10,B:B,B10,C:C,C10,D:D,D10,E:E,E10,F:F,F10) -> 1 | I10: {=_xlfn.UNIQUE(B2:$B$334)} -> Pain Relief Tablets | J10: =COUNTIF(B2:$B$334,I10) -> 39 | L10: {=_xlfn.UNIQUE(F2:$F$334)} -> Australia | M10: =COUNTIF(F2:$F$334,L10) -> 53 | O10: {=_xlfn.UNIQUE(C2:$C$334)} -> Divya Mehra | P10: =COUNTIF(C2:$C$334,O10) -> 48
A11: =IF(Raw_data!A11="",NA(),Raw_data!A11) -> 44585 | B11: =IF(Raw_data!B11="",NA(),Raw_data!B11) -> Antiseptic Cream | C11: =IF(Raw_data!C11="",NA(),Raw_data!C11) -> Sneha Iyer | D11: =IF(Raw_data!D11="",NA(),Raw_data!D11) -> 7 | E11: =IF(Raw_data!E11="",NA(),Raw_data!E11) -> 89.29 | F11: =IF(Raw_data!F11="",NA(),Raw_data!F11) -> Australia | G11: =COUNTIFS(A:A,A11,B:B,B11,C:C,C11,D:D,D11,E:E,E11,F:F,F11) -> 1 | I11: Antiseptic Cream | J11: =COUNTIF(B3:$B$334,I11) -> 56 | L11: Canada | M11: =COUNTIF(F3:$F$334,L11) -> 65 | O11: Nikhil Batra | P11: =COUNTIF(C3:$C$334,O11) -> 52
A12: =IF(Raw_data!A12="",NA(),Raw_data!A12) -> 44678 | B12: =IF(Raw_data!B12="",NA(),Raw_data!B12) -> Cough Syrup | C12: =IF(Raw_data!C12="",NA(),Raw_data!C12) -> Divya Mehra | D12: =IF(Raw_data!D12="",NA(),Raw_data!D12) -> 11 | E12: =IF(Raw_data!E12="",NA(),Raw_data!E12) -> 150.73 | F12: =IF(Raw_data!F12="",NA(),Raw_data!F12) -> Canada | G12: =COUNTIFS(A:A,A12,B:B,B12,C:C,C12,D:D,D12,E:E,E12,F:F,F12) -> 1 | I12: Cough Syrup | J12: =COUNTIF(B4:$B$334,I12) -> 41 | L12: UK | M12: =COUNTIF(F4:$F$334,L12) -> 74 | O12: Ritika Shah | P12: =COUNTIF(C4:$C$334,O12) -> 44
A13: =IF(Raw_data!A13="",NA(),Raw_data!A13) -> 44610 | B13: =IF(Raw_data!B13="",NA(),Raw_data!B13) -> Pain Relief Tablets | C13: =IF(Raw_data!C13="",NA(),Raw_data!C13) -> Ritika Shah | D13: =IF(Raw_data!D13="",NA(),Raw_data!D13) -> 5 | E13: =IF(Raw_data!E13="",NA(),Raw_data!E13) -> 63.41 | F13: =IF(Raw_data!F13="",NA(),Raw_data!F13) -> USA | G13: =COUNTIFS(A:A,A13,B:B,B13,C:C,C13,D:D,D13,E:E,E13,F:F,F13) -> 1 | I13: Digestive Enzyme | J13: =COUNTIF(B5:$B$334,I13) -> 51 | L13: USA | M13: =COUNTIF(F5:$F$334,L13) -> 77 | O13: Priya Singh | P13: =COUNTIF(C5:$C$334,O13) -> 54
A14: =IF(Raw_data!A14="",NA(),Raw_data!A14) -> 44738 | B14: =IF(Raw_data!B14="",NA(),Raw_data!B14) -> Pain Relief Tablets | C14: =IF(Raw_data!C14="",NA(),Raw_data!C14) -> Divya Mehra | D14: =IF(Raw_data!D14="",NA(),Raw_data!D14) -> 18 | E14: =IF(Raw_data!E14="",NA(),Raw_data!E14) -> 175.89 | F14: =IF(Raw_data!F14="",NA(),Raw_data!F14) -> USA | G14: =COUNTIFS(A:A,A14,B:B,B14,C:C,C14,D:D,D14,E:E,E14,F:F,F14) -> 1 | I14: Eye Drops | J14: =COUNTIF(B6:$B$334,I14) -> 49 | L14: India | M14: =COUNTIF(F6:$F$334,L14) -> 64 | O14: Sneha Iyer | P14: =COUNTIF(C6:$C$334,O14) -> 35
A15: =IF(Raw_data!A15="",NA(),Raw_data!A15) -> 44731 | B15: =IF(Raw_data!B15="",NA(),Raw_data!B15) -> Nasal Spray | C15: =IF(Raw_data!C15="",NA(),Raw_data!C15) -> Priya Singh | D15: =IF(Raw_data!D15="",NA(),Raw_data!D15) -> 18 | E15: =IF(Raw_data!E15="",NA(),Raw_data!E15) -> 296.97 | F15: =IF(Raw_data!F15="",NA(),Raw_data!F15) -> Australia | G15: =COUNTIFS(A:A,A15,B:B,B15,C:C,C15,D:D,D15,E:E,E15,F:F,F15) -> 1 | I15: Nasal Spray | J15: =COUNTIF(B7:$B$334,I15) -> 47 | O15: Rajesh Patel | P15: =COUNTIF(C7:$C$334,O15) -> 55
A16: =IF(Raw_data!A16="",NA(),Raw_data!A16) -> 44715 | B16: =IF(Raw_data!B16="",NA(),Raw_data!B16) -> Cough Syrup | C16: =IF(Raw_data!C16="",NA(),Raw_data!C16) -> Ritika Shah | D16: =IF(Raw_data!D16="",NA(),Raw_data!D16) -> 12 | E16: =IF(Raw_data!E16="",NA(),Raw_data!E16) -> 177.75 | F16: =IF(Raw_data!F16="",NA(),Raw_data!F16) -> USA | G16: =COUNTIFS(A:A,A16,B:B,B16,C:C,C16,D:D,D16,E:E,E16,F:F,F16) -> 1 | I16: Allergy Pills | J16: =COUNTIF(B8:$B$334,I16) -> 50 | O16: Aman Verma | P16: =COUNTIF(C8:$C$334,O16) -> 45
A17: =IF(Raw_data!A17="",NA(),Raw_data!A17) -> 44656 | B17: =IF(Raw_data!B17="",NA(),Raw_data!B17) -> Cough Syrup | C17: =IF(Raw_data!C17="",NA(),Raw_data!C17) -> Nikhil Batra | D17: =IF(Raw_data!D17="",NA(),Raw_data!D17) -> 14 | E17: =IF(Raw_data!E17="",NA(),Raw_data!E17) -> 285.09 | F17: =IF(Raw_data!F17="",NA(),Raw_data!F17) -> Canada | G17: =COUNTIFS(A:A,A17,B:B,B17,C:C,C17,D:D,D17,E:E,E17,F:F,F17) -> 1
A18: =IF(Raw_data!A18="",NA(),Raw_data!A18) -> 44668 | B18: =IF(Raw_data!B18="",NA(),Raw_data!B18) -> Pain Relief Tablets | C18: =IF(Raw_data!C18="",NA(),Raw_data!C18) -> Ritika Shah | D18: =IF(Raw_data!D18="",NA(),Raw_data!D18) -> 12 | E18: =IF(Raw_data!E18="",NA(),Raw_data!E18) -> 277.22 | F18: =IF(Raw_data!F18="",NA(),Raw_data!F18) -> Australia | G18: =COUNTIFS(A:A,A18,B:B,B18,C:C,C18,D:D,D18,E:E,E18,F:F,F18) -> 1 | I18: Column1 | J18: Column2
A19: =IF(Raw_data!A19="",NA(),Raw_data!A19) -> 44603 | B19: =IF(Raw_data!B19="",NA(),Raw_data!B19) -> Nasal Spray | C19: =IF(Raw_data!C19="",NA(),Raw_data!C19) -> Priya Singh | D19: =IF(Raw_data!D19="",NA(),Raw_data!D19) -> 17 | E19: =IF(Raw_data!E19="",NA(),Raw_data!E19) -> 175.18 | F19: =IF(Raw_data!F19="",NA(),Raw_data!F19) -> Canada | G19: =COUNTIFS(A:A,A19,B:B,B19,C:C,C19,D:D,D19,E:E,E19,F:F,F19) -> 1 | I19: Digestive Enzyme | J19: 216.79627
A20: =IF(Raw_data!A20="",NA(),Raw_data!A20) -> 44579 | B20: =IF(Raw_data!B20="",NA(),Raw_data!B20) -> Antiseptic Cream | C20: =IF(Raw_data!C20="",NA(),Raw_data!C20) -> Ritika Shah | D20: =IF(Raw_data!D20="",NA(),Raw_data!D20) -> 12 | E20: =IF(Raw_data!E20="",NA(),Raw_data!E20) -> 192.16 | F20: =IF(Raw_data!F20="",NA(),Raw_data!F20) -> Australia | G20: =COUNTIFS(A:A,A20,B:B,B20,C:C,C20,D:D,D20,E:E,E20,F:F,F20) -> 1 | I20: Cough Syrup | J20: 193.0978
A21: =IF(Raw_data!A21="",NA(),Raw_data!A21) -> 44711 | B21: =IF(Raw_data!B21="",NA(),Raw_data!B21) -> Allergy Pills | C21: =IF(Raw_data!C21="",NA(),Raw_data!C21) -> Nikhil Batra | D21: =IF(Raw_data!D21="",NA(),Raw_data!D21) -> 9 | E21: =IF(Raw_data!E21="",NA(),Raw_data!E21) -> 123.12 | F21: =IF(Raw_data!F21="",NA(),Raw_data!F21) -> India | G21: =COUNTIFS(A:A,A21,B:B,B21,C:C,C21,D:D,D21,E:E,E21,F:F,F21) -> 1 | I21: Nasal Spray | J21: 178.88
A22: =IF(Raw_data!A22="",NA(),Raw_data!A22) -> 44730 | B22: =IF(Raw_data!B22="",NA(),Raw_data!B22) -> Pain Relief Tablets | C22: =IF(Raw_data!C22="",NA(),Raw_data!C22) -> Divya Mehra | D22: =IF(Raw_data!D22="",NA(),Raw_data!D22) -> 15 | E22: =IF(Raw_data!E22="",NA(),Raw_data!E22) -> 238.86 | F22: =IF(Raw_data!F22="",NA(),Raw_data!F22) -> Australia | G22: =COUNTIFS(A:A,A22,B:B,B22,C:C,C22,D:D,D22,E:E,E22,F:F,F22) -> 1 | I22: Antiseptic Cream | J22: 173.86214
A23: =IF(Raw_data!A23="",NA(),Raw_data!A23) -> 44748 | B23: =IF(Raw_data!B23="",NA(),Raw_data!B23) -> Eye Drops | C23: =IF(Raw_data!C23="",NA(),Raw_data!C23) -> Sneha Iyer | D23: =IF(Raw_data!D23="",NA(),Raw_data!D23) -> 20 | E23: =IF(Raw_data!E23="",NA(),Raw_data!E23) -> 272.37 | F23: =IF(Raw_data!F23="",NA(),Raw_data!F23) -> UK | G23: =COUNTIFS(A:A,A23,B:B,B23,C:C,C23,D:D,D23,E:E,E23,F:F,F23) -> 1 | I23: Eye Drops | J23: 164.00735
A24: =IF(Raw_data!A24="",NA(),Raw_data!A24) -> 44706 | B24: =IF(Raw_data!B24="",NA(),Raw_data!B24) -> Allergy Pills | C24: =IF(Raw_data!C24="",NA(),Raw_data!C24) -> Rajesh Patel | D24: =IF(Raw_data!D24="",NA(),Raw_data!D24) -> 8 | E24: =IF(Raw_data!E24="",NA(),Raw_data!E24) -> 82.86 | F24: =IF(Raw_data!F24="",NA(),Raw_data!F24) -> USA | G24: =COUNTIFS(A:A,A24,B:B,B24,C:C,C24,D:D,D24,E:E,E24,F:F,F24) -> 1 | I24: Allergy Pills | J24: 155.6516
A25: =IF(Raw_data!A25="",NA(),Raw_data!A25) -> 44677 | B25: =IF(Raw_data!B25="",NA(),Raw_data!B25) -> Eye Drops | C25: =IF(Raw_data!C25="",NA(),Raw_data!C25) -> Aman Verma | D25: =IF(Raw_data!D25="",NA(),Raw_data!D25) -> 19 | E25: =IF(Raw_data!E25="",NA(),Raw_data!E25) -> 447.21 | F25: =IF(Raw_data!F25="",NA(),Raw_data!F25) -> India | G25: =COUNTIFS(A:A,A25,B:B,B25,C:C,C25,D:D,D25,E:E,E25,F:F,F25) -> 1 | I25: Pain Relief Tablets | J25: 153.66897
A26: =IF(Raw_data!A26="",NA(),Raw_data!A26) -> 44738 | B26: =IF(Raw_data!B26="",NA(),Raw_data!B26) -> Eye Drops | C26: =IF(Raw_data!C26="",NA(),Raw_data!C26) -> Priya Singh | D26: =IF(Raw_data!D26="",NA(),Raw_data!D26) -> 1 | E26: =IF(Raw_data!E26="",NA(),Raw_data!E26) -> 9.98 | F26: =IF(Raw_data!F26="",NA(),Raw_data!F26) -> Canada | G26: =COUNTIFS(A:A,A26,B:B,B26,C:C,C26,D:D,D26,E:E,E26,F:F,F26) -> 1
A27: =IF(Raw_data!A27="",NA(),Raw_data!A27) -> 44743 | B27: =IF(Raw_data!B27="",NA(),Raw_data!B27) -> Pain Relief Tablets | C27: =IF(Raw_data!C27="",NA(),Raw_data!C27) -> Rajesh Patel | D27: =IF(Raw_data!D27="",NA(),Raw_data!D27) -> 5 | E27: =IF(Raw_data!E27="",NA(),Raw_data!E27) -> 101.4 | F27: =IF(Raw_data!F27="",NA(),Raw_data!F27) -> India | G27: =COUNTIFS(A:A,A27,B:B,B27,C:C,C27,D:D,D27,E:E,E27,F:F,F27) -> 1
A28: =IF(Raw_data!A28="",NA(),Raw_data!A28) -> 44801 | B28: =IF(Raw_data!B28="",NA(),Raw_data!B28) -> Digestive Enzyme | C28: =IF(Raw_data!C28="",NA(),Raw_data!C28) -> Sneha Iyer | D28: =IF(Raw_data!D28="",NA(),Raw_data!D28) -> 13 | E28: =IF(Raw_data!E28="",NA(),Raw_data!E28) -> 206.79 | F28: =IF(Raw_data!F28="",NA(),Raw_data!F28) -> India | G28: =COUNTIFS(A:A,A28,B:B,B28,C:C,C28,D:D,D28,E:E,E28,F:F,F28) -> 1
A29: =IF(Raw_data!A29="",NA(),Raw_data!A29) -> 44750 | B29: =IF(Raw_data!B29="",NA(),Raw_data!B29) -> Allergy Pills | C29: =IF(Raw_data!C29="",NA(),Raw_data!C29) -> Aman Verma | D29: =IF(Raw_data!D29="",NA(),Raw_data!D29) -> 11 | E29: =IF(Raw_data!E29="",NA(),Raw_data!E29) -> 153.08 | F29: =IF(Raw_data!F29="",NA(),Raw_data!F29) -> UK | G29: =COUNTIFS(A:A,A29,B:B,B29,C:C,C29,D:D,D29,E:E,E29,F:F,F29) -> 1
A30: =IF(Raw_data!A30="",NA(),Raw_data!A30) -> 44595 | B30: =IF(Raw_data!B30="",NA(),Raw_data!B30) -> Digestive Enzyme | C30: =IF(Raw_data!C30="",NA(),Raw_data!C30) -> Aman Verma | D30: =IF(Raw_data!D30="",NA(),Raw_data!D30) -> 18 | E30: =IF(Raw_data!E30="",NA(),Raw_data!E30) -> 411.44 | F30: =IF(Raw_data!F30="",NA(),Raw_data!F30) -> USA | G30: =COUNTIFS(A:A,A30,B:B,B30,C:C,C30,D:D,D30,E:E,E30,F:F,F30) -> 1
A31: =IF(Raw_data!A31="",NA(),Raw_data!A31) -> 44637 | B31: =IF(Raw_data!B31="",NA(),Raw_data!B31) -> Allergy Pills | C31: =IF(Raw_data!C31="",NA(),Raw_data!C31) -> Rajesh Patel | D31: =IF(Raw_data!D31="",NA(),Raw_data!D31) -> 5 | E31: =IF(Raw_data!E31="",NA(),Raw_data!E31) -> 46.92 | F31: =IF(Raw_data!F31="",NA(),Raw_data!F31) -> Canada | G31: =COUNTIFS(A:A,A31,B:B,B31,C:C,C31,D:D,D31,E:E,E31,F:F,F31) -> 1
A32: =IF(Raw_data!A32="",NA(),Raw_data!A32) -> 44737 | B32: =IF(Raw_data!B32="",NA(),Raw_data!B32) -> Cough Syrup | C32: =IF(Raw_data!C32="",NA(),Raw_data!C32) -> Divya Mehra | D32: =IF(Raw_data!D32="",NA(),Raw_data!D32) -> 3 | E32: =IF(Raw_data!E32="",NA(),Raw_data!E32) -> 42.85 | F32: =IF(Raw_data!F32="",NA(),Raw_data!F32) -> UK | G32: =COUNTIFS(A:A,A32,B:B,B32,C:C,C32,D:D,D32,E:E,E32,F:F,F32) -> 1
A33: =IF(Raw_data!A33="",NA(),Raw_data!A33) -> 44723 | B33: =IF(Raw_data!B33="",NA(),Raw_data!B33) -> Eye Drops | C33: =IF(Raw_data!C33="",NA(),Raw_data!C33) -> Priya Singh | D33: =IF(Raw_data!D33="",NA(),Raw_data!D33) -> 2 | E33: =IF(Raw_data!E33="",NA(),Raw_data!E33) -> 40.17 | F33: =IF(Raw_data!F33="",NA(),Raw_data!F33) -> UK | G33: =COUNTIFS(A:A,A33,B:B,B33,C:C,C33,D:D,D33,E:E,E33,F:F,F33) -> 1
A34: =IF(Raw_data!A34="",NA(),Raw_data!A34) -> 44649 | B34: =IF(Raw_data!B34="",NA(),Raw_data!B34) -> Antiseptic Cream | C34: =IF(Raw_data!C34="",NA(),Raw_data!C34) -> Rajesh Patel | D34: =IF(Raw_data!D34="",NA(),Raw_data!D34) -> 13 | E34: =IF(Raw_data!E34="",NA(),Raw_data!E34) -> 243.79 | F34: =IF(Raw_data!F34="",NA(),Raw_data!F34) -> Canada | G34: =COUNTIFS(A:A,A34,B:B,B34,C:C,C34,D:D,D34,E:E,E34,F:F,F34) -> 1
A35: =IF(Raw_data!A35="",NA(),Raw_data!A35) -> 44646 | B35: =IF(Raw_data!B35="",NA(),Raw_data!B35) -> Antiseptic Cream | C35: =IF(Raw_data!C35="",NA(),Raw_data!C35) -> Priya Singh | D35: =IF(Raw_data!D35="",NA(),Raw_data!D35) -> 2 | E35: =IF(Raw_data!E35="",NA(),Raw_data!E35) -> 44.86 | F35: =IF(Raw_data!F35="",NA(),Raw_data!F35) -> UK | G35: =COUNTIFS(A:A,A35,B:B,B35,C:C,C35,D:D,D35,E:E,E35,F:F,F35) -> 1
A36: =IF(Raw_data!A36="",NA(),Raw_data!A36) -> 44757 | B36: =IF(Raw_data!B36="",NA(),Raw_data!B36) -> Digestive Enzyme | C36: =IF(Raw_data!C36="",NA(),Raw_data!C36) -> Nikhil Batra | D36: =IF(Raw_data!D36="",NA(),Raw_data!D36) -> 19 | E36: =IF(Raw_data!E36="",NA(),Raw_data!E36) -> 288.4 | F36: =IF(Raw_data!F36="",NA(),Raw_data!F36) -> UK | G36: =COUNTIFS(A:A,A36,B:B,B36,C:C,C36,D:D,D36,E:E,E36,F:F,F36) -> 1
A37: =IF(Raw_data!A37="",NA(),Raw_data!A37) -> 44758 | B37: =IF(Raw_data!B37="",NA(),Raw_data!B37) -> Cough Syrup | C37: =IF(Raw_data!C37="",NA(),Raw_data!C37) -> Aman Verma | D37: =IF(Raw_data!D37="",NA(),Raw_data!D37) -> 9 | E37: =IF(Raw_data!E37="",NA(),Raw_data!E37) -> 137.02 | F37: =IF(Raw_data!F37="",NA(),Raw_data!F37) -> India | G37: =COUNTIFS(A:A,A37,B:B,B37,C:C,C37,D:D,D37,E:E,E37,F:F,F37) -> 1
... A334: =IF(Raw_data!A334="",NA(),Raw_data!A334) -> 44784 | B334: =IF(Raw_data!B334="",NA(),Raw_data!B334) -> Digestive Enzyme | C334: =IF(Raw_data!C334="",NA(),Raw_data!C334) -> Rajesh Patel | D334: =IF(Raw_data!D334="",NA(),Raw_data!D334) -> 3 | E334: =IF(Raw_data!E334="",NA(),Raw_data!E334) -> 65.98 | F334: =IF(Raw_data!F334="",NA(),Raw_data!F334) -> UK | G334: =COUNTIFS(A:A,A334,B:B,B334,C:C,C334,D:D,D334,E:E,E334,F:F,F334) -> 1

Sheet Data_analysis
A3: Product | B3: Total Amount | D3: Product | E3: Total box | G3: Amount | H3: Distribution | J3: Country | K3: Total Amount | M3: Product | N3: AVG Amount | P3: KPIS | Q3: Column1
A4: Digestive Enzyme | B4: 11056.61 | D4: Digestive Enzyme | E4: 612 | G4: 8.09-28.09 | H4: 18 | J4: Australia | K4: 9698.37 | M4: Digestive Enzyme | N4: 216.79627 | P4: GMV | Q4: =SUM(Cleanning_data!E2:E334) -> 58929.29
A5: Antiseptic Cream | B5: 9736.28 | D5: Antiseptic Cream | E5: 573 | G5: 28.09-48.09 | H5: 27 | J5: Allergy Pills | K5: 1249.78 | M5: Cough Syrup | N5: 193.0978 | P5: Total order | Q5: =SUM(Cleanning_data!D2:D334) -> 3488
A6: Nasal Spray | B6: 8407.36 | D6: Allergy Pills | E6: 518 | G6: 48.09-68.09 | H6: 33 | J6: Antiseptic Cream | K6: 1105.15 | M6: Nasal Spray | N6: 178.88 | P6: AOV | Q6: =ROUND(AVERAGE(Cleanning_data!E2:E334),2) -> 176.96
A7: Eye Drops | B7: 8036.36 | D7: Nasal Spray | E7: 489 | G7: 68.09-88.09 | H7: 17 | J7: Cough Syrup | K7: 1344.19 | M7: Antiseptic Cream | N7: 173.86214
A8: Cough Syrup | B8: 7917.01 | D8: Cough Syrup | E8: 484 | G8: 88.09-108.09 | H8: 25 | J8: Digestive Enzyme | K8: 1427.21 | M8: Eye Drops | N8: 164.00735
A9: Allergy Pills | B9: 7782.58 | D9: Eye Drops | E9: 458 | G9: 108.09-128.09 | H9: 13 | J9: Eye Drops | K9: 1301.97 | M9: Allergy Pills | N9: 155.6516
A10: Pain Relief Tablets | B10: 5993.09 | D10: Pain Relief Tablets | E10: 354 | G10: 128.09-148.09 | H10: 21 | J10: Nasal Spray | K10: 1905.15 | M10: Pain Relief Tablets | N10: 153.66897
A11: Grand Total | B11: 58929.29 | D11: Grand Total | E11: 3488 | G11: 148.09-168.09 | H11: 27 | J11: Pain Relief Tablets | K11: 1364.92 | M11: Grand Total | N11: 176.96483
G12: 168.09-188.09 | H12: 18 | J12: Canada | K12: 11967.08
A13: Sales Person | B13: Total Amount | D13: Sales Person | E13: Total box | G13: 188.09-208.09 | H13: 16 | J13: Allergy Pills | K13: 935.98 | M13: Sales Person | N13: AVG Amount
A14: Rajesh Patel | B14: 11023.53 | D14: Rajesh Patel | E14: 614 | G14: 208.09-228.09 | H14: 19 | J14: Antiseptic Cream | K14: 2337.25 | M14: Rajesh Patel | N14: 200.42782
A15: Nikhil Batra | B15: 10416.34 | D15: Nikhil Batra | E15: 565 | G15: 228.09-248.09 | H15: 15 | J15: Cough Syrup | K15: 1088.37 | M15: Nikhil Batra | N15: 200.31423
A16: Priya Singh | B16: 9121.78 | D16: Priya Singh | E16: 558 | G16: 248.09-268.09 | H16: 2 | J16: Digestive Enzyme | K16: 3074.51 | M16: Sneha Iyer | N16: 185.32714
A17: Ritika Shah | B17: 7945.97 | D17: Aman Verma | E17: 466 | G17: 268.09-288.09 | H17: 11 | J17: Eye Drops | K17: 1744.65 | M17: Ritika Shah | N17: 180.59023
A18: Aman Verma | B18: 7039.07 | D18: Divya Mehra | E18: 455 | G18: 288.09-308.09 | H18: 13 | J18: Nasal Spray | K18: 1473.18 | M18: Priya Singh | N18: 168.92185
A19: Divya Mehra | B19: 6896.15 | D19: Ritika Shah | E19: 449 | G19: 308.09-328.09 | H19: 15 | J19: Pain Relief Tablets | K19: 1313.14 | M19: Aman Verma | N19: 156.42378
A20: Sneha Iyer | B20: 6486.45 | D20: Sneha Iyer | E20: 381 | G20: 328.09-348.09 | H20: 9 | J20: India | K20: 11122.06 | M20: Divya Mehra | N20: 143.66979
A21: Grand Total | B21: 58929.29 | D21: Grand Total | E21: 3488 | G21: 348.09-368.09 | H21: 7 | J21: Allergy Pills | K21: 2211.94 | M21: Grand Total | N21: 176.96483
G22: 368.09-388.09 | H22: 7 | J22: Antiseptic Cream | K22: 2395.66
A23: Country | B23: Total Amount | D23: Country | E23: Total box | G23: 388.09-408.09 | H23: 4 | J23: Cough Syrup | K23: 1046.8 | M23: Country | N23: AVG Amount
A24: USA | B24: 14109.48 | D24: Australia | E24: 587 | G24: 408.09-428.09 | H24: 5 | J24: Digestive Enzyme | K24: 2151.36 | M24: Canada | N24: 184.10892
A25: UK | B25: 12032.3 | D25: Canada | E25: 689 | G25: 428.09-448.09 | H25: 5 | J25: Eye Drops | K25: 1454.75 | M25: USA | N25: 183.24
A26: Canada | B26: 11967.08 | D26: India | E26: 665 | G26: 468.09-488.09 | H26: 5 | J26: Nasal Spray | K26: 1048.05 | M26: Australia | N26: 182.98811
A27: India | B27: 11122.06 | D27: UK | E27: 752 | G27: 488.09-508.09 | H27: 1 | J27: Pain Relief Tablets | K27: 813.5 | M27: India | N27: 173.78219
A28: Australia | B28: 9698.37 | D28: USA | E28: 795 | G28: Grand Total | H28: 333 | J28: UK | K28: 12032.3 | M28: UK | N28: 162.59865
A29: Grand Total | B29: 58929.29 | D29: Grand Total | E29: 3488 | J29: Allergy Pills | K29: 1199.72 | M29: Grand Total | N29: 176.96483
G30: Total box | H30: Distribution | J30: Antiseptic Cream | K30: 1403.43
A31: Month | B31: Total Amount | D31: Month | E31: Total box | G31: 1-2 | H31: 38 | J31: Cough Syrup | K31: 2759.13 | M31: Month | N31: AVG Amount
A32: Jan | B32: 5536.39 | D32: Jan | E32: 350 | G32: 3-4 | H32: 32 | J32: Digestive Enzyme | K32: 2558.06 | M32: Jan | N32: 173.01219
A33: Feb | B33: 7451.5 | D33: Feb | E33: 418 | G33: 5-6 | H33: 33 | J33: Eye Drops | K33: 1177.99 | M33: Feb | N33: 173.2907
A34: Mar | B34: 7062.15 | D34: Mar | E34: 425 | G34: 7-8 | H34: 35 | J34: Nasal Spray | K34: 2365.9 | M34: Mar | N34: 196.17083
A35: Apr | B35: 7339.15 | D35: Apr | E35: 403 | G35: 9-10 | H35: 27 | J35: Pain Relief Tablets | K35: 568.07 | M35: Apr | N35: 198.35541
A36: May | B36: 8885 | D36: May | E36: 524 | G36: 11-12 | H36: 32 | J36: USA | K36: 14109.48 | M36: May | N36: 181.32653
A37: Jun | B37: 7019.56 | D37: Jun | E37: 452 | G37: 13-14 | H37: 33 | J37: Allergy Pills | K37: 2185.16 | M37: Jun | N37: 155.99022
A38: Jul | B38: 8754.44 | D38: Jul | E38: 520 | G38: 15-16 | H38: 31 | J38: Antiseptic Cream | K38: 2494.79 | M38: Jul | N38: 178.66204
A39: Aug | B39: 6881.1 | D39: Aug | E39: 396 | G39: 17-18 | H39: 36 | J39: Cough Syrup | K39: 1678.52 | M39: Aug | N39: 163.83571
A40: Grand Total | B40: 58929.29 | D40: Grand Total | E40: 3488 | G40: 19-20 | H40: 36 | J40: Digestive Enzyme | K40: 1845.47 | M40: Grand Total | N40: 176.96483
G41: Grand Total | H41: 333 | J41: Eye Drops | K41: 2357
A42: Date | B42: Total Amount | D42: Month | E42: Total box | J42: Nasal Spray | K42: 1615.08 | M42: Date | N42: AVG Amount
...

Sheet Dashboardtab1

Sheet Dashboardtab2

Sheet Insights_and_Recomendations
